<?xml version="1.0" ?>
<robot name="youbot">
  <joint name="youbot__base_footprint_joint" type="fixed">
    <parent link="youbot__base_footprint"/>
    <child link="youbot__base_link"/>
    <origin rpy="0  0  0" xyz="0    0    0.09"/>
    <axis xyz="0  0  1"/>
    <limit effort="0.0" lower="0.0" upper="0.0" velocity="0.0"/>
  </joint>
  <joint name="youbot__arm_joint_0" type="fixed">
    <parent link="youbot__base_link"/>
    <child link="youbot__arm_link_0"/>
    <origin rpy="0  0  0" xyz="0.14299  0       0.046"/>
    <axis xyz="0  0  1"/>
    <limit effort="0.0" lower="0.0" upper="0.0" velocity="0.0"/>
  </joint>
  <joint name="youbot__arm_joint_1" type="revolute">
    <parent link="youbot__arm_link_0"/>
    <child link="youbot__arm_link_1"/>
    <origin rpy="0       0       2.96706" xyz="0.024  0     0.096"/>
    <axis xyz="0  0 -1"/>
    <limit effort="9.5" lower="0.0" upper="5.899213" velocity="0.0"/>
  </joint>
  <joint name="youbot__arm_joint_2" type="revolute">
    <parent link="youbot__arm_link_1"/>
    <child link="youbot__arm_link_2"/>
    <origin rpy="0      -1.13446  0" xyz="0.033  0     0.019"/>
    <axis xyz="0  1  0"/>
    <limit effort="9.5" lower="0.0" upper="2.70526" velocity="-1.0"/>
  </joint>
  <joint name="youbot__arm_joint_3" type="revolute">
    <parent link="youbot__arm_link_2"/>
    <child link="youbot__arm_link_3"/>
    <origin rpy="3.14159  0.59341  3.14159" xyz="0     0     0.155"/>
    <axis xyz="0  1  0"/>
    <limit effort="6.0" lower="-5.183628" upper="0.0" velocity="-1.0"/>
  </joint>
  <joint name="youbot__arm_joint_4" type="revolute">
    <parent link="youbot__arm_link_3"/>
    <child link="youbot__arm_link_4"/>
    <origin rpy="-3.14159 -1.35262  3.14159" xyz="0     0     0.135"/>
    <axis xyz="0  1  0"/>
    <limit effort="2.0" lower="0.0" upper="3.577925" velocity="-1.0"/>
  </joint>
  <joint name="youbot__arm_joint_5" type="revolute">
    <parent link="youbot__arm_link_4"/>
    <child link="youbot__arm_link_5"/>
    <origin rpy="0       0       2.92342" xyz="-0.002  0     0.13"/>
    <axis xyz="0  0 -1"/>
    <limit effort="1.0" lower="0.0" upper="5.846853" velocity="-1.0"/>
  </joint>
  <joint name="youbot__gripper_palm_joint" type="fixed">
    <parent link="youbot__arm_link_5"/>
    <child link="youbot__gripper_palm_link"/>
    <origin rpy="0  0  0" xyz="0  0  0"/>
    <axis xyz="-0.35781 -0.07932  0.93041"/>
    <limit effort="0.0" lower="0.0" upper="0.0" velocity="0.0"/>
  </joint>
  <joint name="youbot__gripper_finger_joint_l" type="prismatic">
    <parent link="youbot__gripper_palm_link"/>
    <child link="youbot__gripper_finger_link_l"/>
    <origin rpy="0       0      -3.14159" xyz="0.00399  0.008    0.04599"/>
    <axis xyz="0 -1  0"/>
    <limit effort="1.0" lower="0.0" upper="0.0115" velocity="-1.0"/>
  </joint>
  <joint name="youbot__gripper_finger_joint_r" type="prismatic">
    <parent link="youbot__gripper_palm_link"/>
    <child link="youbot__gripper_finger_link_r"/>
    <origin rpy="0  0  0" xyz="0.004   -0.008    0.04599"/>
    <axis xyz="0 -1  0"/>
    <limit effort="1.0" lower="0.0" upper="0.0115" velocity="-1.0"/>
  </joint>
  <joint name="youbot__base_laser_front_hokuyo_urg04_laser_joint" type="fixed">
    <parent link="youbot__base_link"/>
    <child link="youbot__base_laser_front_link"/>
    <origin rpy="0  0  0" xyz="0.3   0   -0.03"/>
    <axis xyz="0  0  1"/>
    <limit effort="0.0" lower="0.0" upper="0.0" velocity="0.0"/>
  </joint>
  <joint name="youbot__caster_joint_bl" type="fixed">
    <parent link="youbot__base_link"/>
    <child link="youbot__caster_link_bl"/>
    <origin rpy="0  0  0" xyz="-0.228  0.158 -0.034"/>
    <axis xyz="0  0  1"/>
    <limit effort="1.0" lower="0.0" upper="0.0" velocity="0.0"/>
  </joint>
  <joint name="youbot__wheel_joint_bl" type="fixed">
    <parent link="youbot__caster_link_bl"/>
    <child link="youbot__wheel_link_bl"/>
    <origin rpy="0  0  0" xyz="0  0  0"/>
    <axis xyz="0  1  0"/>
    <limit effort="1.0" lower="0.0" upper="0.0" velocity="0.0"/>
  </joint>
  <joint name="youbot__caster_joint_br" type="fixed">
    <parent link="youbot__base_link"/>
    <child link="youbot__caster_link_br"/>
    <origin rpy="0  0  0" xyz="-0.228 -0.158 -0.034"/>
    <axis xyz="0  0  1"/>
    <limit effort="1.0" lower="0.0" upper="0.0" velocity="0.0"/>
  </joint>
  <joint name="youbot__wheel_joint_br" type="fixed">
    <parent link="youbot__caster_link_br"/>
    <child link="youbot__wheel_link_br"/>
    <origin rpy="0  0  0" xyz="0  0  0"/>
    <axis xyz="0  1  0"/>
    <limit effort="1.0" lower="0.0" upper="0.0" velocity="0.0"/>
  </joint>
  <joint name="youbot__caster_joint_fl" type="fixed">
    <parent link="youbot__base_link"/>
    <child link="youbot__caster_link_fl"/>
    <origin rpy="0  0  0" xyz="0.228  0.158 -0.034"/>
    <axis xyz="0  0  1"/>
    <limit effort="1.0" lower="0.0" upper="0.0" velocity="0.0"/>
  </joint>
  <joint name="youbot__wheel_joint_fl" type="fixed">
    <parent link="youbot__caster_link_fl"/>
    <child link="youbot__wheel_link_fl"/>
    <origin rpy="0  0  0" xyz="0  0  0"/>
    <axis xyz="0  1  0"/>
    <limit effort="1.0" lower="0.0" upper="0.0" velocity="0.0"/>
  </joint>
  <joint name="youbot__caster_joint_fr" type="fixed">
    <parent link="youbot__base_link"/>
    <child link="youbot__caster_link_fr"/>
    <origin rpy="0  0  0" xyz="0.228 -0.158 -0.034"/>
    <axis xyz="0  0  1"/>
    <limit effort="1.0" lower="0.0" upper="0.0" velocity="0.0"/>
  </joint>
  <joint name="youbot__wheel_joint_fr" type="fixed">
    <parent link="youbot__caster_link_fr"/>
    <child link="youbot__wheel_link_fr"/>
    <origin rpy="0  0  0" xyz="0  0  0"/>
    <axis xyz="0  1  0"/>
    <limit effort="1.0" lower="0.0" upper="0.0" velocity="0.0"/>
  </joint>
  <joint name="youbot__plate_joint" type="fixed">
    <parent link="youbot__base_link"/>
    <child link="youbot__plate_link"/>
    <origin rpy="0  0  0" xyz="-0.159  0     0.046"/>
    <axis xyz="0  0  1"/>
    <limit effort="0.0" lower="0.0" upper="0.0" velocity="0.0"/>
  </joint>
  <link name="youbot__base_footprint">
    <inertial>
      <mass value="0.100000"/>
      <origin rpy="0  0  0" xyz="0    0   -0.05"/>
      <inertia ixx="1" ixy="0" ixz="0" iyy="1" iyz="0" izz="1"/>
    </inertial>
    <collision name="youbot__base_footprint_geom">
      <origin rpy="0  0  0" xyz="0    0    0.04"/>
      <geometry>
        <box size="0.001000 0.001000 0.001000"/>
      </geometry>
    </collision>
    <visual name="youbot__base_footprint_geom_visual">
      <origin rpy="0  0  0" xyz="0    0    0.09"/>
      <geometry>
        <box size="0.001000 0.001000 0.001000"/>
      </geometry>
    </visual>
  </link>
  <link name="youbot__base_link">
    <inertial>
      <mass value="22.000000"/>
      <origin rpy="0  0  0" xyz="0  0  0"/>
      <inertia ixx="5.652230" ixy="-0.009720" ixz="1.293990" iyy="5.669470" iyz="-0.007380" izz="3.683200"/>
    </inertial>
    <collision name="youbot__base_link_geom">
      <origin rpy="0  0  0" xyz="0  0  0"/>
      <geometry>
        <mesh filename="package://wro_gazebo/models/youbot/meshes/base/base_convex.stl" scale="1.0 1.0 1.0"/>
      </geometry>
    </collision>
    <visual name="youbot__base_link_geom_visual">
      <origin rpy="0  0  0" xyz="0  0  0"/>
      <geometry>
        <mesh filename="package://wro_gazebo/models/youbot/meshes/base/base.dae" scale="1.0 1.0 1.0"/>
      </geometry>
    </visual>
  </link>
  <link name="youbot__arm_link_0">
    <inertial>
      <mass value="0.845000"/>
      <origin rpy="0  0  0" xyz="0  0  0"/>
      <inertia ixx="0.010000" ixy="0" ixz="0" iyy="0.010000" iyz="0" izz="0.010000"/>
    </inertial>
    <collision name="youbot__arm_link_0_geom">
      <origin rpy="0  0  0" xyz="0  0  0"/>
      <geometry>
        <mesh filename="package://wro_gazebo/models/youbot/meshes/arm/arm0_convex.stl" scale="1.0 1.0 1.0"/>
      </geometry>
    </collision>
    <visual name="youbot__arm_link_0_geom_visual">
      <origin rpy="0  0  0" xyz="0  0  0"/>
      <geometry>
        <mesh filename="package://wro_gazebo/models/youbot/meshes/arm/arm0.dae" scale="1.0 1.0 1.0"/>
      </geometry>
    </visual>
  </link>
  <link name="youbot__arm_link_1">
    <inertial>
      <mass value="2.412000"/>
      <origin rpy="0  0  0" xyz="0.01489  0.00213  0.00213"/>
      <inertia ixx="0.003863" ixy="-0.000979" ixz="0" iyy="0.006196" iyz="0" izz="0.006369"/>
    </inertial>
    <collision name="youbot__arm_link_1_geom">
      <origin rpy="0  0  0" xyz="0  0  0"/>
      <geometry>
        <mesh filename="package://wro_gazebo/models/youbot/meshes/arm/arm1_convex.stl" scale="1.0 1.0 1.0"/>
      </geometry>
    </collision>
    <visual name="youbot__arm_link_1_geom_visual">
      <origin rpy="0  0  0" xyz="0  0  0"/>
      <geometry>
        <mesh filename="package://wro_gazebo/models/youbot/meshes/arm/arm1.dae" scale="1.0 1.0 1.0"/>
      </geometry>
    </visual>
  </link>
  <link name="youbot__arm_link_2">
    <inertial>
      <mass value="1.155000"/>
      <origin rpy="0  0  0" xyz="0.10453  0.0017  -0.00297"/>
      <inertia ixx="0.000823" ixy="0" ixz="-0.000000" iyy="0.004447" iyz="0" izz="0.004439"/>
    </inertial>
    <collision name="youbot__arm_link_2_geom">
      <origin rpy="0  0  0" xyz="0    -0.032  0.078"/>
      <geometry>
        <mesh filename="package://wro_gazebo/models/youbot/meshes/arm/arm2_convex.stl" scale="1.0 1.0 1.0"/>
      </geometry>
    </collision>
    <visual name="youbot__arm_link_2_geom_visual">
      <origin rpy="0  0  0" xyz="0    -0.032  0.078"/>
      <geometry>
        <mesh filename="package://wro_gazebo/models/youbot/meshes/arm/arm2.dae" scale="1.0 1.0 1.0"/>
      </geometry>
    </visual>
  </link>
  <link name="youbot__arm_link_3">
    <inertial>
      <mass value="0.934000"/>
      <origin rpy="0  0  0" xyz="0.0001   0.0967   0.02107"/>
      <inertia ixx="0.002459" ixy="0" ixz="0" iyy="0.002571" iyz="-0.000000" izz="0.000535"/>
    </inertial>
    <collision name="youbot__arm_link_3_geom">
      <origin rpy="0  0  0" xyz="0     0.028  0.079"/>
      <geometry>
        <mesh filename="package://wro_gazebo/models/youbot/meshes/arm/arm3_convex.stl" scale="1.0 1.0 1.0"/>
      </geometry>
    </collision>
    <visual name="youbot__arm_link_3_geom_visual">
      <origin rpy="0  0  0" xyz="0     0.028  0.079"/>
      <geometry>
        <mesh filename="package://wro_gazebo/models/youbot/meshes/arm/arm3.dae" scale="1.0 1.0 1.0"/>
      </geometry>
    </visual>
  </link>
  <link name="youbot__arm_link_4">
    <inertial>
      <mass value="0.877000"/>
      <origin rpy="0  0  0" xyz="0.00011  0.05103 -0.02319"/>
      <inertia ixx="0.000869" ixy="0" ixz="-0.000000" iyy="0.001173" iyz="-0.000231" izz="0.001091"/>
    </inertial>
    <collision name="youbot__arm_link_4_geom">
      <origin rpy="0  0  0" xyz="0    -0.01   0.029"/>
      <geometry>
        <mesh filename="package://wro_gazebo/models/youbot/meshes/arm/arm4_convex.stl" scale="1.0 1.0 1.0"/>
      </geometry>
    </collision>
    <visual name="youbot__arm_link_4_geom_visual">
      <origin rpy="0  0  0" xyz="0    -0.01   0.029"/>
      <geometry>
        <mesh filename="package://wro_gazebo/models/youbot/meshes/arm/arm4.dae" scale="1.0 1.0 1.0"/>
      </geometry>
    </visual>
  </link>

  <link name="youbot__arm_link_5">
    <inertial>
      <mass value="0.251000"/>
      <origin rpy="0  0  0" xyz="0       0.00115 -0.01683"/>
      <inertia ixx="0.000280" ixy="0" ixz="0" iyy="0.000339" iyz="0" izz="0.000119"/>
    </inertial>
    <collision name="youbot__arm_link_5_geom">
      <origin rpy="0  0  0" xyz="0.003  0    -0.034"/>
      <geometry>
        <mesh filename="package://wro_gazebo/models/youbot/meshes/arm/arm5_convex.stl" scale="1.0 1.0 1.0"/>
      </geometry>
    </collision>
    <visual name="youbot__arm_link_5_geom_visual">
      <origin rpy="0  0  0" xyz="0.003  0    -0.034"/>
      <geometry>
        <mesh filename="package://wro_gazebo/models/youbot/meshes/arm/arm5.dae" scale="1.0 1.0 1.0"/>
      </geometry>
    </visual>
  </link>

  <link name="youbot__gripper_palm_link">
    <inertial>
      <mass value="0.100000"/>
      <origin rpy="0  0  0" xyz="0  0  0"/>
      <inertia ixx="0.010000" ixy="0" ixz="0" iyy="0.010000" iyz="0" izz="0.010000"/>
    </inertial>
    <collision name="youbot__gripper_palm_link_geom">
      <origin rpy="0  0  0" xyz="0  0  0"/>
      <geometry>
        <mesh filename="package://wro_gazebo/models/youbot/meshes/gripper/palm_convex.stl" scale="1.0 1.0 1.0"/>
      </geometry>
    </collision>
    <visual name="youbot__gripper_palm_link_geom_visual">
      <origin rpy="0  0  0" xyz="0  0  0"/>
      <geometry>
        <mesh filename="package://wro_gazebo/models/youbot/meshes/gripper/palm.stl" scale="1.0 1.0 1.0"/>
      </geometry>
    </visual>
  </link>
  <link name="youbot__gripper_finger_link_l">
    <inertial>
      <mass value="0.010000"/>
      <origin rpy="0  0  0" xyz="0    -0.001  0"/>
      <inertia ixx="0.010000" ixy="0" ixz="0" iyy="0.010000" iyz="0" izz="0.010000"/>
    </inertial>
    <collision name="youbot__gripper_finger_link_l_geom">
      <origin rpy="0  0  0" xyz="0  0  0"/>
      <geometry>
        <mesh filename="package://wro_gazebo/models/youbot/meshes/gripper/finger_convex.stl" scale="1.0 1.0 1.0"/>
      </geometry>
    </collision>
    <visual name="youbot__gripper_finger_link_l_geom_visual">
      <origin rpy="0  0  0" xyz="0  0  0"/>
      <geometry>
        <mesh filename="package://wro_gazebo/models/youbot/meshes/gripper/finger.stl" scale="1.0 1.0 1.0"/>
      </geometry>
    </visual>
  </link>
  <link name="youbot__gripper_finger_link_r">
    <inertial>
      <mass value="0.010000"/>
      <origin rpy="0  0  0" xyz="0    -0.001  0"/>
      <inertia ixx="0.010000" ixy="0" ixz="0" iyy="0.010000" iyz="0" izz="0.010000"/>
    </inertial>
    <collision name="youbot__gripper_finger_link_r_geom">
      <origin rpy="0  0  0" xyz="0  0  0"/>
      <geometry>
        <mesh filename="package://wro_gazebo/models/youbot/meshes/gripper/finger_convex.stl" scale="1.0 1.0 1.0"/>
      </geometry>
    </collision>
    <visual name="youbot__gripper_finger_link_r_geom_visual">
      <origin rpy="0  0  0" xyz="0  0  0"/>
      <geometry>
        <mesh filename="package://wro_gazebo/models/youbot/meshes/gripper/finger.stl" scale="1.0 1.0 1.0"/>
      </geometry>
    </visual>
  </link>
  <link name="youbot__base_laser_front_link">
    <inertial>
      <mass value="0.160000"/>
      <origin rpy="0  0  0" xyz="0  0  0"/>
      <inertia ixx="0.100000" ixy="0" ixz="0" iyy="0.100000" iyz="0" izz="0.100000"/>
    </inertial>
    <collision name="youbot__base_laser_front_link_geom">
      <origin rpy="0  0  0" xyz="0  0  0"/>
      <geometry>
        <mesh filename="package://wro_gazebo/models/hokuyo/meshes/hokuyo_convex.stl" scale="1.0 1.0 1.0"/>
      </geometry>
    </collision>
    <visual name="youbot__base_laser_front_link_geom_visual">
      <origin rpy="0  0  0" xyz="0  0  0"/>
      <geometry>
        <mesh filename="package://wro_gazebo/models/hokuyo/meshes/hokuyo.dae" scale="1.0 1.0 1.0"/>
      </geometry>
    </visual>
  </link>
  <link name="youbot__caster_link_bl">
    <inertial>
      <mass value="0.100000"/>
      <origin rpy="0  0  0" xyz="0  0  0"/>
      <inertia ixx="0.012412" ixy="-0.000712" ixz="0.000503" iyy="0.015218" iyz="-0.000004" izz="0.011764"/>
    </inertial>
  </link>
  <link name="youbot__wheel_link_bl">
    <inertial>
      <mass value="0.400000"/>
      <origin rpy="0  0  0" xyz="0  0  0"/>
      <inertia ixx="0.012412" ixy="-0.000712" ixz="0.000503" iyy="0.015218" iyz="-0.000004" izz="0.011764"/>
    </inertial>
    <collision name="youbot__wheel_link_bl_geom">
      <origin rpy="1.5708  0      0" xyz="0  0  0"/>
      <geometry>
        <cylinder length="0.005000" radius="0.050000"/>
      </geometry>
    </collision>
    <visual name="youbot__wheel_link_bl_geom_visual">
      <origin rpy="0  0  0" xyz="0  0  0"/>
      <geometry>
        <mesh filename="package://wro_gazebo/models/youbot/meshes/base/back-left_wheel.dae" scale="1.0 1.0 1.0"/>
      </geometry>
    </visual>
  </link>
  <link name="youbot__caster_link_br">
    <inertial>
      <mass value="0.100000"/>
      <origin rpy="0  0  0" xyz="0  0  0"/>
      <inertia ixx="0.012412" ixy="-0.000712" ixz="0.000503" iyy="0.015218" iyz="-0.000004" izz="0.011764"/>
    </inertial>
  </link>
  <link name="youbot__wheel_link_br">
    <inertial>
      <mass value="0.400000"/>
      <origin rpy="0  0  0" xyz="0  0  0"/>
      <inertia ixx="0.012412" ixy="-0.000712" ixz="0.000503" iyy="0.015218" iyz="-0.000004" izz="0.011764"/>
    </inertial>
    <collision name="youbot__wheel_link_br_geom">
      <origin rpy="1.5708  0      0" xyz="0  0  0"/>
      <geometry>
        <cylinder length="0.005000" radius="0.050000"/>
      </geometry>
    </collision>
    <visual name="youbot__wheel_link_br_geom_visual">
      <origin rpy="0  0  0" xyz="0  0  0"/>
      <geometry>
        <mesh filename="package://wro_gazebo/models/youbot/meshes/base/back-right_wheel.dae" scale="1.0 1.0 1.0"/>
      </geometry>
    </visual>
  </link>
  <link name="youbot__caster_link_fl">
    <inertial>
      <mass value="0.100000"/>
      <origin rpy="0  0  0" xyz="0  0  0"/>
      <inertia ixx="0.012412" ixy="-0.000712" ixz="0.000503" iyy="0.015218" iyz="-0.000004" izz="0.011764"/>
    </inertial>
  </link>
  <link name="youbot__wheel_link_fl">
    <inertial>
      <mass value="0.400000"/>
      <origin rpy="0  0  0" xyz="0  0  0"/>
      <inertia ixx="0.012412" ixy="-0.000712" ixz="0.000503" iyy="0.015218" iyz="-0.000004" izz="0.011764"/>
    </inertial>
    <collision name="youbot__wheel_link_fl_geom">
      <origin rpy="1.5708  0      0" xyz="0  0  0"/>
      <geometry>
        <cylinder length="0.005000" radius="0.050000"/>
      </geometry>
    </collision>
    <visual name="youbot__wheel_link_fl_geom_visual">
      <origin rpy="0  0  0" xyz="0  0  0"/>
      <geometry>
        <mesh filename="package://wro_gazebo/models/youbot/meshes/base/front-left_wheel.dae" scale="1.0 1.0 1.0"/>
      </geometry>
    </visual>
  </link>
  <link name="youbot__caster_link_fr">
    <inertial>
      <mass value="0.100000"/>
      <origin rpy="0  0  0" xyz="0  0  0"/>
      <inertia ixx="0.012412" ixy="-0.000712" ixz="0.000503" iyy="0.015218" iyz="-0.000004" izz="0.011764"/>
    </inertial>
  </link>
  <link name="youbot__wheel_link_fr">
    <inertial>
      <mass value="0.400000"/>
      <origin rpy="0  0  0" xyz="0  0  0"/>
      <inertia ixx="0.012412" ixy="-0.000712" ixz="0.000503" iyy="0.015218" iyz="-0.000004" izz="0.011764"/>
    </inertial>
    <collision name="youbot__wheel_link_fr_geom">
      <origin rpy="1.5708  0      0" xyz="0  0  0"/>
      <geometry>
        <cylinder length="0.005000" radius="0.050000"/>
      </geometry>
    </collision>
    <visual name="youbot__wheel_link_fr_geom_visual">
      <origin rpy="0  0  0" xyz="0  0  0"/>
      <geometry>
        <mesh filename="package://wro_gazebo/models/youbot/meshes/base/front-right_wheel.dae" scale="1.0 1.0 1.0"/>
      </geometry>
    </visual>
  </link>
  <link name="youbot__plate_link">
    <inertial>
      <mass value="1"/>
      <origin rpy="0  0  0" xyz="0  0  0"/>
      <inertia ixx="0.010000" ixy="0" ixz="0" iyy="0.010000" iyz="0" izz="0.010000"/>
    </inertial>
    <collision name="youbot__plate_link_geom">
      <origin rpy="0  0  0" xyz="0  0  0"/>
      <geometry>
        <mesh filename="package://wro_gazebo/models/youbot/meshes/plate/plate_convex.stl" scale="1.0 1.0 1.0"/>
      </geometry>
    </collision>
    <visual name="youbot__plate_link_geom_visual">
      <origin rpy="0  0  0" xyz="0  0  0"/>
      <geometry>
        <mesh filename="package://wro_gazebo/models/youbot/meshes/plate/plate.dae" scale="1.0 1.0 1.0"/>
      </geometry>
    </visual>
  </link>

<transmission name="tran1">
    <type>transmission_interface/SimpleTransmission</type>
    <joint name="youbot__arm_joint_1">
      <hardwareInterface>hardware_interface/EffortJointInterface</hardwareInterface>
    </joint>
    <actuator name="motor1">
      <hardwareInterface>hardware_interface/EffortJointInterface</hardwareInterface>
      <mechanicalReduction>1</mechanicalReduction>
    </actuator>
  </transmission>

  <transmission name="tran2">
    <type>transmission_interface/SimpleTransmission</type>
    <joint name="youbot__arm_joint_2">
      <hardwareInterface>hardware_interface/EffortJointInterface</hardwareInterface>
    </joint>
    <actuator name="motor2">
      <hardwareInterface>hardware_interface/EffortJointInterface</hardwareInterface>
      <mechanicalReduction>1</mechanicalReduction>
    </actuator>
  </transmission>

<gazebo>
  <plugin name="gazebo_ros_control" filename="libgazebo_ros_control.so">
    <robotNamespace>/youbot</robotNamespace>
<legacyModeNS>true</legacyModeNS>
  </plugin>
</gazebo>

</robot>
