<!-- Notes -->
<!-- This is a modification of the actual 'KUKA YOUBOT' and does not simulate mechanum wheels -->
<!-- The robot URDF is modified by eliminating links and joints used to simulate mechanum wheels -->
<!-- The Hokuyo laserscanner mounted on the robot is replaced by a Kinect Camera -->
<!-- The robot manipulator is controlled using effort_controllers/JointPositionController -->
<?xml version="1.0" ?>
<robot name="youbot">
  <joint name="youbot__base_footprint_joint" type="revolute">
    <parent link="youbot__base_footprint"/>
    <child link="youbot__base_link"/>
    <origin rpy="0  0  0" xyz="0    0    0.09"/>
    <axis xyz="0  0  1"/>
    <limit effort="0.0" lower="0.0" upper="0.0" velocity="0.0"/>
  </joint>
  <joint name="youbot__arm_joint_0" type="revolute">
    <parent link="youbot__base_link"/>
    <child link="youbot__arm_link_0"/>
    <origin rpy="0  0  0" xyz="0.14299  0       0.046"/>
    <axis xyz="0  0  1"/>
    <limit effort="0.0" lower="0.0" upper="0.0" velocity="0.0"/>
  </joint>
  <joint name="youbot__arm_joint_1" type="revolute">
    <parent link="youbot__arm_link_0"/>
    <child link="youbot__arm_link_1"/>
    <origin rpy="0       0       2.96706" xyz="0.024  0     0.096"/>
    <axis xyz="0  0 -1"/>
    <limit effort="9.5" lower="0.0" upper="5.899213" velocity="1.0"/>
  </joint>
  <joint name="youbot__arm_joint_2" type="revolute">
    <parent link="youbot__arm_link_1"/>
    <child link="youbot__arm_link_2"/>
    <origin rpy="0      -1.13446  0" xyz="0.033  0     0.019"/>
    <axis xyz="0  1  0"/>
    <limit effort="9.5" lower="0.0" upper="2.70526" velocity="1.0"/>
  </joint>
  <joint name="youbot__arm_joint_3" type="revolute">
    <parent link="youbot__arm_link_2"/>
    <child link="youbot__arm_link_3"/>
    <origin rpy="3.14159  0.59341  3.14159" xyz="0     0     0.155"/>
    <axis xyz="0  1  0"/>
    <limit effort="6.0" lower="-5.183628" upper="0.0" velocity="1.0"/>
  </joint>
  <joint name="youbot__arm_joint_4" type="revolute">
    <parent link="youbot__arm_link_3"/>
    <child link="youbot__arm_link_4"/>
    <origin rpy="-3.14159 -1.35262  3.14159" xyz="0     0     0.135"/>
    <axis xyz="0  1  0"/>
    <limit effort="2.0" lower="0.0" upper="3.577925" velocity="1.0"/>
  </joint>
  <joint name="youbot__arm_joint_5" type="revolute">
    <parent link="youbot__arm_link_4"/>
    <child link="youbot__arm_link_5"/>
    <origin rpy="0       0       2.92342" xyz="-0.002  0     0.13"/>
    <axis xyz="0  0 -1"/>
    <limit effort="1.0" lower="0.0" upper="5.846853" velocity="1.0"/>
  </joint>
  <joint name="youbot__gripper_palm_joint" type="revolute">
    <parent link="youbot__arm_link_5"/>
    <child link="youbot__gripper_palm_link"/>
    <origin rpy="0  0  0" xyz="0  0  0"/>
    <axis xyz="-0.35781 -0.07932  0.93041"/>
    <limit effort="0.0" lower="0.0" upper="0.0" velocity="0.0"/>
  </joint>
  <joint name="youbot__gripper_finger_joint_l" type="prismatic">
    <parent link="youbot__gripper_palm_link"/>
    <child link="youbot__gripper_finger_link_l"/>
    <origin rpy="0       0      -3.14159" xyz="0.00399  0.008    0.04599"/>
    <axis xyz="0 -1  0"/>
    <limit effort="1.0" lower="0.0" upper="0.0115" velocity="-1.0"/>
  </joint>
  <joint name="youbot__gripper_finger_joint_r" type="prismatic">
    <parent link="youbot__gripper_palm_link"/>
    <child link="youbot__gripper_finger_link_r"/>
    <origin rpy="0  0  0" xyz="0.004   -0.008    0.04599"/>
    <axis xyz="0 -1  0"/>
    <limit effort="1.0" lower="0.0" upper="0.0115" velocity="1.0"/>
  </joint>
  <joint name="youbot__base_laser_front_hokuyo_urg04_laser_joint" type="revolute">
    <parent link="youbot__base_link"/>
    <child link="kinect__link"/>
    <origin rpy="0  0  0" xyz="0.33   0   0.03"/>
    <axis xyz="0  0  1"/>
    <limit effort="0.0" lower="0.0" upper="0.0" velocity="0.0"/>
  </joint>

<!--  <joint name="youbot__caster_joint_bl" type="revolute">
    <parent link="youbot__base_link"/>
    <child link="youbot__caster_link_bl"/>
    <origin rpy="0  0  0" xyz="-0.228  0.158 -0.034"/>
    <axis xyz="0  0  1"/>
    <limit effort="1.0" lower="0.0" upper="0.0" velocity="0.0"/>
  </joint> -->
  <joint name="youbot__wheel_joint_bl" type="continuous">
    <parent link="youbot__base_link"/>
    <child link="youbot__wheel_link_bl"/>
    <origin rpy="0  0  0" xyz="-0.228  0.158 -0.034"/>
    <axis xyz="0  1  0"/>
    <limit effort="10.0" velocity="250.0"/>
  </joint>
  <!-- <joint name="youbot__caster_joint_br" type="revolute">
    <parent link="youbot__base_link"/>
    <child link="youbot__caster_link_br"/>
    <origin rpy="0  0  0" xyz="-0.228 -0.158 -0.034"/>
    <axis xyz="0  0  1"/>
    <limit effort="1.0" lower="0.0" upper="0.0" velocity="0.0"/>
  </joint> -->
  <joint name="youbot__wheel_joint_br" type="continuous">
    <parent link="youbot__base_link"/>
    <child link="youbot__wheel_link_br"/>
    <origin rpy="0  0  0" xyz="-0.228 -0.158 -0.034"/>
    <axis xyz="0  1  0"/>
    <limit effort="10.0" velocity="250.0"/>
  </joint>
  <!-- <joint name="youbot__caster_joint_fl" type="revolute">
    <parent link="youbot__base_link"/>
    <child link="youbot__caster_link_fl"/>
    <origin rpy="0  0  0" xyz="0.228  0.158 -0.034"/>
    <axis xyz="0  0  1"/>
    <limit effort="1.0" lower="0.0" upper="0.0" velocity="0.0"/>
  </joint> -->
  <joint name="youbot__wheel_joint_fl" type="continuous">
    <parent link="youbot__base_link"/>
    <child link="youbot__wheel_link_fl"/>
    <origin rpy="0  0  0" xyz="0.228  0.158 -0.034"/>
    <axis xyz="0  1  0"/>
    <limit effort="10.0" velocity="250.0"/>
  </joint>
  <!-- <joint name="youbot__caster_joint_fr" type="revolute">
    <parent link="youbot__base_link"/>
    <child link="youbot__caster_link_fr"/>
    <origin rpy="0  0  0" xyz="0.228 -0.158 -0.034"/>
    <axis xyz="0  0  1"/>
    <limit effort="1.0" lower="0.0" upper="0.0" velocity="0.0"/>
  </joint> -->
  <joint name="youbot__wheel_joint_fr" type="continuous">
    <parent link="youbot__base_link"/>
    <child link="youbot__wheel_link_fr"/>
    <origin rpy="0  0  0" xyz="0.228 -0.158 -0.034"/>
    <axis xyz="0  1  0"/>
    <limit effort="10.0" velocity="250.0"/>
  </joint>
  <joint name="youbot__plate_joint" type="revolute">
    <parent link="youbot__base_link"/>
    <child link="youbot__plate_link"/>
    <origin rpy="0  0  0" xyz="-0.159  0     0.046"/>
    <axis xyz="0  0  1"/>
    <limit effort="0.0" lower="0.0" upper="0.0" velocity="0.0"/>
  </joint>
  <link name="youbot__base_footprint">
    <inertial>
      <mass value="0.100000"/>
      <origin rpy="0  0  0" xyz="0    0   -0.05"/>
      <inertia ixx="1" ixy="0" ixz="0" iyy="1" iyz="0" izz="1"/>
    </inertial>
    <collision name="youbot__base_footprint_geom">
      <origin rpy="0  0  0" xyz="0    0    0.04"/>
      <geometry>
        <box size="0.001000 0.001000 0.001000"/>
      </geometry>
    </collision>
    <visual name="youbot__base_footprint_geom_visual">
      <origin rpy="0  0  0" xyz="0    0    0.09"/>
      <geometry>
        <box size="0.001000 0.001000 0.001000"/>
      </geometry>
    </visual>
  </link>
  <link name="youbot__base_link">
    <inertial>
      <mass value="22.000000"/>
      <origin rpy="0  0  0" xyz="0  0  0"/>
      <inertia ixx="5.652230" ixy="-0.009720" ixz="1.293990" iyy="5.669470" iyz="-0.007380" izz="3.683200"/>
    </inertial>
    <collision name="youbot__base_link_geom">
      <origin rpy="0  0  0" xyz="0  0  0"/>
      <geometry>
        <mesh filename="package://wro_gazebo/models/youbot/meshes/base/base_convex.stl" scale="1.0 1.0 1.0"/>
      </geometry>
    </collision>
    <visual name="youbot__base_link_geom_visual">
      <origin rpy="0  0  0" xyz="0  0  0"/>
      <geometry>
        <mesh filename="package://wro_gazebo/models/youbot/meshes/base/base.dae" scale="1.0 1.0 1.0"/>
      </geometry>
    </visual>
  </link>
  <link name="youbot__arm_link_0">
    <inertial>
      <mass value="0.845000"/>
      <origin rpy="0  0  0" xyz="0  0  0"/>
      <inertia ixx="0.010000" ixy="0" ixz="0" iyy="0.010000" iyz="0" izz="0.010000"/>
    </inertial>
    <collision name="youbot__arm_link_0_geom">
      <origin rpy="0  0  0" xyz="0  0  0"/>
      <geometry>
        <mesh filename="package://wro_gazebo/models/youbot/meshes/arm/arm0_convex.stl" scale="1.0 1.0 1.0"/>
      </geometry>
    </collision>
    <visual name="youbot__arm_link_0_geom_visual">
      <origin rpy="0  0  0" xyz="0  0  0"/>
      <geometry>
        <mesh filename="package://wro_gazebo/models/youbot/meshes/arm/arm0.dae" scale="1.0 1.0 1.0"/>
      </geometry>
    </visual>
  </link>
  <link name="youbot__arm_link_1">
    <inertial>
      <mass value="2.412000"/>
      <origin rpy="0  0  0" xyz="0.01489  0.00213  0.00213"/>
      <inertia ixx="0.003863" ixy="-0.000979" ixz="0" iyy="0.006196" iyz="0" izz="0.006369"/>
    </inertial>
    <collision name="youbot__arm_link_1_geom">
      <origin rpy="0  0  0" xyz="0  0  0"/>
      <geometry>
        <mesh filename="package://wro_gazebo/models/youbot/meshes/arm/arm1_convex.stl" scale="1.0 1.0 1.0"/>
      </geometry>
    </collision>
    <visual name="youbot__arm_link_1_geom_visual">
      <origin rpy="0  0  0" xyz="0  0  0"/>
      <geometry>
        <mesh filename="package://wro_gazebo/models/youbot/meshes/arm/arm1.dae" scale="1.0 1.0 1.0"/>
      </geometry>
    </visual>
  </link>
  <link name="youbot__arm_link_2">
    <inertial>
      <mass value="1.155000"/>
      <origin rpy="0  0  0" xyz="0.10453  0.0017  -0.00297"/>
      <inertia ixx="0.000823" ixy="0" ixz="-0.000000" iyy="0.004447" iyz="0" izz="0.004439"/>
    </inertial>
    <collision name="youbot__arm_link_2_geom">
      <origin rpy="0  0  0" xyz="0    -0.032  0.078"/>
      <geometry>
        <mesh filename="package://wro_gazebo/models/youbot/meshes/arm/arm2_convex.stl" scale="1.0 1.0 1.0"/>
      </geometry>
    </collision>
    <visual name="youbot__arm_link_2_geom_visual">
      <origin rpy="0  0  0" xyz="0    -0.032  0.078"/>
      <geometry>
        <mesh filename="package://wro_gazebo/models/youbot/meshes/arm/arm2.dae" scale="1.0 1.0 1.0"/>
      </geometry>
    </visual>
  </link>
  <link name="youbot__arm_link_3">
    <inertial>
      <mass value="0.934000"/>
      <origin rpy="0  0  0" xyz="0.0001   0.0967   0.02107"/>
      <inertia ixx="0.002459" ixy="0" ixz="0" iyy="0.002571" iyz="-0.000000" izz="0.000535"/>
    </inertial>
    <collision name="youbot__arm_link_3_geom">
      <origin rpy="0  0  0" xyz="0     0.028  0.079"/>
      <geometry>
        <mesh filename="package://wro_gazebo/models/youbot/meshes/arm/arm3_convex.stl" scale="1.0 1.0 1.0"/>
      </geometry>
    </collision>
    <visual name="youbot__arm_link_3_geom_visual">
      <origin rpy="0  0  0" xyz="0     0.028  0.079"/>
      <geometry>
        <mesh filename="package://wro_gazebo/models/youbot/meshes/arm/arm3.dae" scale="1.0 1.0 1.0"/>
      </geometry>
    </visual>
  </link>
  <link name="youbot__arm_link_4">
    <inertial>
      <mass value="0.877000"/>
      <origin rpy="0  0  0" xyz="0.00011  0.05103 -0.02319"/>
      <inertia ixx="0.000869" ixy="0" ixz="-0.000000" iyy="0.001173" iyz="-0.000231" izz="0.001091"/>
    </inertial>
    <collision name="youbot__arm_link_4_geom">
      <origin rpy="0  0  0" xyz="0    -0.01   0.029"/>
      <geometry>
        <mesh filename="package://wro_gazebo/models/youbot/meshes/arm/arm4_convex.stl" scale="1.0 1.0 1.0"/>
      </geometry>
    </collision>
    <visual name="youbot__arm_link_4_geom_visual">
      <origin rpy="0  0  0" xyz="0    -0.01   0.029"/>
      <geometry>
        <mesh filename="package://wro_gazebo/models/youbot/meshes/arm/arm4.dae" scale="1.0 1.0 1.0"/>
      </geometry>
    </visual>
  </link>
  <link name="youbot__arm_link_5">
    <inertial>
      <mass value="0.251000"/>
      <origin rpy="0  0  0" xyz="0       0.00115 -0.01683"/>
      <inertia ixx="0.000280" ixy="0" ixz="0" iyy="0.000339" iyz="0" izz="0.000119"/>
    </inertial>
    <collision name="youbot__arm_link_5_geom">
      <origin rpy="0  0  0" xyz="0.003  0    -0.034"/>
      <geometry>
        <mesh filename="package://wro_gazebo/models/youbot/meshes/arm/arm5_convex.stl" scale="1.0 1.0 1.0"/>
      </geometry>
    </collision>
    <visual name="youbot__arm_link_5_geom_visual">
      <origin rpy="0  0  0" xyz="0.003  0    -0.034"/>
      <geometry>
        <mesh filename="package://wro_gazebo/models/youbot/meshes/arm/arm5.dae" scale="1.0 1.0 1.0"/>
      </geometry>
    </visual>
  </link>
  <link name="youbot__gripper_palm_link">
    <inertial>
      <mass value="0.100000"/>
      <origin rpy="0  0  0" xyz="0  0  0"/>
      <inertia ixx="0.010000" ixy="0" ixz="0" iyy="0.010000" iyz="0" izz="0.010000"/>
    </inertial>
    <collision name="youbot__gripper_palm_link_geom">
      <origin rpy="0  0  0" xyz="0  0  0"/>
      <geometry>
        <mesh filename="package://wro_gazebo/models/youbot/meshes/gripper/palm_convex.stl" scale="1.0 1.0 1.0"/>
      </geometry>
    </collision>
    <visual name="youbot__gripper_palm_link_geom_visual">
      <origin rpy="0  0  0" xyz="0  0  0"/>
      <geometry>
        <mesh filename="package://wro_gazebo/models/youbot/meshes/gripper/palm.stl" scale="1.0 1.0 1.0"/>
      </geometry>
    </visual>
  </link>
  <link name="youbot__gripper_finger_link_l">
    <inertial>
      <mass value="0.010000"/>
      <origin rpy="0  0  0" xyz="0    -0.001  0"/>
      <inertia ixx="0.010000" ixy="0" ixz="0" iyy="0.010000" iyz="0" izz="0.010000"/>
    </inertial>
    <collision name="youbot__gripper_finger_link_l_geom">
      <origin rpy="0  0  0" xyz="0  0  0"/>
      <geometry>
        <mesh filename="package://wro_gazebo/models/youbot/meshes/gripper/finger_convex.stl" scale="1.0 1.0 1.0"/>
      </geometry>
    </collision>
    <visual name="youbot__gripper_finger_link_l_geom_visual">
      <origin rpy="0  0  0" xyz="0  0  0"/>
      <geometry>
        <mesh filename="package://wro_gazebo/models/youbot/meshes/gripper/finger.stl" scale="1.0 1.0 1.0"/>
      </geometry>
    </visual>
  </link>
  <link name="youbot__gripper_finger_link_r">
    <inertial>
      <mass value="0.010000"/>
      <origin rpy="0  0  0" xyz="0    -0.001  0"/>
      <inertia ixx="0.010000" ixy="0" ixz="0" iyy="0.010000" iyz="0" izz="0.010000"/>
    </inertial>
    <collision name="youbot__gripper_finger_link_r_geom">
      <origin rpy="0  0  0" xyz="0  0  0"/>
      <geometry>
        <mesh filename="package://wro_gazebo/models/youbot/meshes/gripper/finger_convex.stl" scale="1.0 1.0 1.0"/>
      </geometry>
    </collision>
    <visual name="youbot__gripper_finger_link_r_geom_visual">
      <origin rpy="0  0  0" xyz="0  0  0"/>
      <geometry>
        <mesh filename="package://wro_gazebo/models/youbot/meshes/gripper/finger.stl" scale="1.0 1.0 1.0"/>
      </geometry>
    </visual>
  </link>
  <!-- <link name="youbot__base_laser_front_link">
    <inertial>
      <mass value="0.160000"/>
      <origin rpy="0  0  0" xyz="0  0  0"/>
      <inertia ixx="0.100000" ixy="0" ixz="0" iyy="0.100000" iyz="0" izz="0.100000"/>
    </inertial>
    <collision name="youbot__base_laser_front_link_geom">
      <origin rpy="0  0  0" xyz="0  0  0"/>
      <geometry>
        <mesh filename="package://wro_gazebo/models/hokuyo/meshes/hokuyo_convex.stl" scale="1.0 1.0 1.0"/>
      </geometry>
    </collision>
    <visual name="youbot__base_laser_front_link_geom_visual">
      <origin rpy="0  0  0" xyz="0  0  0"/>
      <geometry>
        <mesh filename="package://wro_gazebo/models/hokuyo/meshes/hokuyo.dae" scale="1.0 1.0 1.0"/>
      </geometry>
    </visual>
  </link> -->
  <!-- <link name="youbot__caster_link_bl">
    <inertial>
      <mass value="0.100000"/>
      <origin rpy="0  0  0" xyz="0  0  0"/>
      <inertia ixx="0.012412" ixy="-0.000712" ixz="0.000503" iyy="0.015218" iyz="-0.000004" izz="0.011764"/>
    </inertial>
  </link> -->
  <link name="youbot__wheel_link_bl">
    <inertial>
      <mass value="0.400000"/>
      <origin rpy="0  0  0" xyz="0  0  0"/>
      <inertia ixx="0.012412" ixy="-0.000712" ixz="0.000503" iyy="0.015218" iyz="-0.000004" izz="0.011764"/>
    </inertial>
    <collision name="youbot__wheel_link_bl_geom">
      <origin rpy="1.5708  0      0" xyz="0  0  0"/>
      <geometry>
        <cylinder length="0.005000" radius="0.050000"/>
      </geometry>
    </collision>
    <visual name="youbot__wheel_link_bl_geom_visual">
      <origin rpy="0  0  0" xyz="0  0  0"/>
      <geometry>
        <mesh filename="package://wro_gazebo/models/youbot/meshes/base/back-left_wheel.dae" scale="1.0 1.0 1.0"/>
      </geometry>
    </visual>
  </link>
  <!-- <link name="youbot__caster_link_br">
    <inertial>
      <mass value="0.100000"/>
      <origin rpy="0  0  0" xyz="0  0  0"/>
      <inertia ixx="0.012412" ixy="-0.000712" ixz="0.000503" iyy="0.015218" iyz="-0.000004" izz="0.011764"/>
    </inertial>
  </link> -->
  <link name="youbot__wheel_link_br">
    <inertial>
      <mass value="0.400000"/>
      <origin rpy="0  0  0" xyz="0  0  0"/>
      <inertia ixx="0.012412" ixy="-0.000712" ixz="0.000503" iyy="0.015218" iyz="-0.000004" izz="0.011764"/>
    </inertial>
    <collision name="youbot__wheel_link_br_geom">
      <origin rpy="1.5708  0      0" xyz="0  0  0"/>
      <geometry>
        <cylinder length="0.005000" radius="0.050000"/>
      </geometry>
    </collision>
    <visual name="youbot__wheel_link_br_geom_visual">
      <origin rpy="0  0  0" xyz="0  0  0"/>
      <geometry>
        <mesh filename="package://wro_gazebo/models/youbot/meshes/base/back-right_wheel.dae" scale="1.0 1.0 1.0"/>
      </geometry>
    </visual>
  </link>
  <!-- <link name="youbot__caster_link_fl">
    <inertial>
      <mass value="0.100000"/>
      <origin rpy="0  0  0" xyz="0  0  0"/>
      <inertia ixx="0.012412" ixy="-0.000712" ixz="0.000503" iyy="0.015218" iyz="-0.000004" izz="0.011764"/>
    </inertial>
  </link> -->
  <link name="youbot__wheel_link_fl">
    <inertial>
      <mass value="0.400000"/>
      <origin rpy="0  0  0" xyz="0  0  0"/>
      <inertia ixx="0.012412" ixy="-0.000712" ixz="0.000503" iyy="0.015218" iyz="-0.000004" izz="0.011764"/>
    </inertial>
    <collision name="youbot__wheel_link_fl_geom">
      <origin rpy="1.5708  0      0" xyz="0  0  0"/>
      <geometry>
        <cylinder length="0.005000" radius="0.050000"/>
      </geometry>
    </collision>
    <visual name="youbot__wheel_link_fl_geom_visual">
      <origin rpy="0  0  0" xyz="0  0  0"/>
      <geometry>
        <mesh filename="package://wro_gazebo/models/youbot/meshes/base/front-left_wheel.dae" scale="1.0 1.0 1.0"/>
      </geometry>
    </visual>
  </link>
  <!-- <link name="youbot__caster_link_fr">
    <inertial>
      <mass value="0.100000"/>
      <origin rpy="0  0  0" xyz="0  0  0"/>
      <inertia ixx="0.012412" ixy="-0.000712" ixz="0.000503" iyy="0.015218" iyz="-0.000004" izz="0.011764"/>
    </inertial>
  </link> -->
  <link name="youbot__wheel_link_fr">
    <inertial>
      <mass value="0.400000"/>
      <origin rpy="0  0  0" xyz="0  0  0"/>
      <inertia ixx="0.012412" ixy="-0.000712" ixz="0.000503" iyy="0.015218" iyz="-0.000004" izz="0.011764"/>
    </inertial>
    <collision name="youbot__wheel_link_fr_geom">
      <origin rpy="1.5708  0      0" xyz="0  0  0"/>
      <geometry>
        <cylinder length="0.005000" radius="0.050000"/>
      </geometry>
    </collision>
    <visual name="youbot__wheel_link_fr_geom_visual">
      <origin rpy="0  0  0" xyz="0  0  0"/>
      <geometry>
        <mesh filename="package://wro_gazebo/models/youbot/meshes/base/front-right_wheel.dae" scale="1.0 1.0 1.0"/>
      </geometry>
    </visual>
  </link>
  <link name="youbot__plate_link">
    <inertial>
      <mass value="1"/>
      <origin rpy="0  0  0" xyz="0  0  0"/>
      <inertia ixx="0.010000" ixy="0" ixz="0" iyy="0.010000" iyz="0" izz="0.010000"/>
    </inertial>
    <collision name="youbot__plate_link_geom">
      <origin rpy="0  0  0" xyz="0  0  0"/>
      <geometry>
        <mesh filename="package://wro_gazebo/models/youbot/meshes/plate/plate_convex.stl" scale="1.0 1.0 1.0"/>
      </geometry>
    </collision>
    <visual name="youbot__plate_link_geom_visual">
      <origin rpy="0  0  0" xyz="0  0  0"/>
      <geometry>
        <mesh filename="package://wro_gazebo/models/youbot/meshes/plate/plate.dae" scale="1.0 1.0 1.0"/>
      </geometry>
    </visual>
  </link>
<link name="kinect__link">
    <inertial>
      <mass value="0.1"/>
      <origin rpy="0  0  0" xyz="0  0  0"/>
      <inertia ixx="0" ixy="0" ixz="0" iyy="0" iyz="0" izz="0"/>
    </inertial>
    <collision name="kinect__collision">
      <origin rpy="0  0  0" xyz="0       0       0.03599"/>
      <geometry>
        <box size="0.073000 0.276000 0.072000"/>
      </geometry>
    </collision>
    <visual name="kinect__visual">
      <origin rpy="0  0  0" xyz="0       0       0.03599"/>
      <geometry>
        <mesh filename="package://wro_gazebo/models/kinect/meshes/kinect.dae" scale="1.0 1.0 1.0"/>
      </geometry>
    </visual>
</link>

<!-- ------------------------------arm transmissions------------------------------ -->
<!-- The transmission elements are required to use ros_control.
     These specify the relationship between a revolute joint and an actuator that will
     be used by ros control (different controller types) to move the joint as desired  -->

<transmission name="tran0">
    <type>transmission_interface/SimpleTransmission</type>
    <joint name="youbot__arm_joint_0">
      <hardwareInterface>hardware_interface/EffortJointInterface</hardwareInterface>
    </joint>
    <actuator name="motor0">
      <hardwareInterface>hardware_interface/EffortJointInterface</hardwareInterface>
      <mechanicalReduction>1</mechanicalReduction>
    </actuator>
  </transmission>
<transmission name="tran1">
    <type>transmission_interface/SimpleTransmission</type>
    <joint name="youbot__arm_joint_1">
      <hardwareInterface>hardware_interface/EffortJointInterface</hardwareInterface>
    </joint>
    <actuator name="motor1">
      <hardwareInterface>hardware_interface/EffortJointInterface</hardwareInterface>
      <mechanicalReduction>1</mechanicalReduction>
    </actuator>
</transmission>
<transmission name="tran2">
    <type>transmission_interface/SimpleTransmission</type>
    <joint name="youbot__arm_joint_2">
      <hardwareInterface>hardware_interface/EffortJointInterface</hardwareInterface>
    </joint>
    <actuator name="motor2">
      <hardwareInterface>hardware_interface/EffortJointInterface</hardwareInterface>
      <mechanicalReduction>1</mechanicalReduction>
    </actuator>
  </transmission>
<transmission name="tran3">
    <type>transmission_interface/SimpleTransmission</type>
    <joint name="youbot__arm_joint_3">
      <hardwareInterface>hardware_interface/EffortJointInterface</hardwareInterface>
    </joint>
    <actuator name="motor3">
      <hardwareInterface>hardware_interface/EffortJointInterface</hardwareInterface>
      <mechanicalReduction>1</mechanicalReduction>
    </actuator>
</transmission>
<transmission name="tran4">
    <type>transmission_interface/SimpleTransmission</type>
    <joint name="youbot__arm_joint_4">
      <hardwareInterface>hardware_interface/EffortJointInterface</hardwareInterface>
    </joint>
    <actuator name="motor4">
      <hardwareInterface>hardware_interface/EffortJointInterface</hardwareInterface>
      <mechanicalReduction>1</mechanicalReduction>
    </actuator>
</transmission>
<transmission name="tran5">
    <type>transmission_interface/SimpleTransmission</type>
    <joint name="youbot__arm_joint_5">
      <hardwareInterface>hardware_interface/EffortJointInterface</hardwareInterface>
    </joint>
    <actuator name="motor5">
      <hardwareInterface>hardware_interface/EffortJointInterface</hardwareInterface>
      <mechanicalReduction>1</mechanicalReduction>
    </actuator>
</transmission>

<!-- ----------------------------Control Plugins------------------------------ -->
<gazebo>
  <plugin name="skid_steer_drive_controller" filename="libgazebo_ros_skid_steer_drive.so"> <!-- Control of quadrature base using Twist Msg -->
    <updateRate>100.0</updateRate>
    <robotNamespace>/youbot</robotNamespace>
    <leftFrontJoint>youbot__wheel_joint_fl</leftFrontJoint>
    <rightFrontJoint>youbot__wheel_joint_fr</rightFrontJoint>
    <leftRearJoint>youbot__wheel_joint_bl</leftRearJoint>
    <rightRearJoint>youbot__wheel_joint_br</rightRearJoint>
    <wheelSeparation>0.316</wheelSeparation>
    <wheelDiameter>0.1</wheelDiameter>
    <robotBaseFrame>base_link</robotBaseFrame>
    <torque>20</torque>
    <topicName>cmd_vel</topicName>
    <broadcastTF>false</broadcastTF>
  </plugin>
</gazebo>

<gazebo>
  <plugin name="gazebo_ros_control" filename="libgazebo_ros_control.so">   <!-- Plugin to enable ros_control (this allows for interfacing Gazebo and ROS by setting up simulated controllers which can accessed using ROS) -->
    <robotNamespace>/youbot</robotNamespace>
    <legacyModeNS>true</legacyModeNS>
  </plugin>
</gazebo>

<gazebo reference="kinect__link">
  <sensor name="camera" type="depth">
    <update_rate>20</update_rate>
    <camera>
      <horizontal_fov>1.047198</horizontal_fov>
      <image>
        <width>640</width>
        <height>480</height>
        <format>R8G8B8</format>
      </image>
      <clip>
        <near>0.05</near>
        <far>3</far>
      </clip>
    </camera>
<plugin name="camera_controller" filename="libgazebo_ros_openni_kinect.so"> <!-- This is a sensor plugin and not a model plugin.-->
          <baseline>0.2</baseline>                                          <!--  Note how the plugin in included inside the sensor tags -->
          <alwaysOn>true</alwaysOn>
          <updateRate>0.0</updateRate>
          <cameraName>camera_ir</cameraName>
          <imageTopicName>/camera/depth/image_raw</imageTopicName>
          <cameraInfoTopicName>/camera/depth/camera_info</cameraInfoTopicName>
          <depthImageTopicName>/camera/depth/image_raw</depthImageTopicName>
          <depthImageInfoTopicName>/camera/depth/camera_info</depthImageInfoTopicName>
          <pointCloudTopicName>/camera/depth/points</pointCloudTopicName>
          <frameName>camera_depth_optical_frame</frameName>
          <pointCloudCutoff>0.05</pointCloudCutoff>
          <distortionK1>0</distortionK1>
          <distortionK2>0</distortionK2>
          <distortionK3>0</distortionK3>
          <distortionT1>0</distortionT1>
          <distortionT2>0</distortionT2>
          <CxPrime>0</CxPrime>
          <Cx>0</Cx>
          <Cy>0</Cy>
          <focalLength>0</focalLength>
          <hackBaseline>0</hackBaseline>
        </plugin>
      </sensor>
</gazebo>
</robot>
